[2025-05-04T18:24:02.801+0000] {local_task_job_runner.py:120} INFO - ::group::Pre task execution logs
[2025-05-04T18:24:02.844+0000] {taskinstance.py:2076} INFO - Dependencies all met for dep_context=non-requeueable deps ti=<TaskInstance: main.task_first manual__2025-05-04T18:23:59.433782+00:00 [queued]>
[2025-05-04T18:24:02.859+0000] {taskinstance.py:2076} INFO - Dependencies all met for dep_context=requeueable deps ti=<TaskInstance: main.task_first manual__2025-05-04T18:23:59.433782+00:00 [queued]>
[2025-05-04T18:24:02.860+0000] {taskinstance.py:2306} INFO - Starting attempt 1 of 1
[2025-05-04T18:24:02.891+0000] {taskinstance.py:2330} INFO - Executing <Task(PythonOperator): task_first> on 2025-05-04 18:23:59.433782+00:00
[2025-05-04T18:24:02.905+0000] {warnings.py:112} WARNING - /home/***/.local/lib/python3.12/site-packages/***/task/task_runner/standard_task_runner.py:61: DeprecationWarning: This process (pid=412) is multi-threaded, use of fork() may lead to deadlocks in the child.
  pid = os.fork()

[2025-05-04T18:24:02.909+0000] {standard_task_runner.py:63} INFO - Started process 413 to run task
[2025-05-04T18:24:02.910+0000] {standard_task_runner.py:90} INFO - Running: ['***', 'tasks', 'run', 'main', 'task_first', 'manual__2025-05-04T18:23:59.433782+00:00', '--job-id', '132', '--raw', '--subdir', 'DAGS_FOLDER/main.py', '--cfg-path', '/tmp/tmpg41v81h5']
[2025-05-04T18:24:02.914+0000] {standard_task_runner.py:91} INFO - Job 132: Subtask task_first
[2025-05-04T18:24:02.997+0000] {task_command.py:426} INFO - Running <TaskInstance: main.task_first manual__2025-05-04T18:23:59.433782+00:00 [running]> on host 3d59bb7e8591
[2025-05-04T18:24:03.266+0000] {taskinstance.py:2648} INFO - Exporting env vars: AIRFLOW_CTX_DAG_OWNER='***' AIRFLOW_CTX_DAG_ID='main' AIRFLOW_CTX_TASK_ID='task_first' AIRFLOW_CTX_EXECUTION_DATE='2025-05-04T18:23:59.433782+00:00' AIRFLOW_CTX_TRY_NUMBER='1' AIRFLOW_CTX_DAG_RUN_ID='manual__2025-05-04T18:23:59.433782+00:00'
[2025-05-04T18:24:03.269+0000] {taskinstance.py:430} INFO - ::endgroup::
[2025-05-04T18:24:13.404+0000] {logging_mixin.py:188} INFO - Файл не найден
[2025-05-04T18:24:13.406+0000] {taskinstance.py:441} INFO - ::group::Post task execution logs
[2025-05-04T18:24:13.408+0000] {taskinstance.py:2905} ERROR - Task failed with exception
Traceback (most recent call last):
  File "/opt/airflow/dags/main.py", line 38, in DownloadCSV
    df_auto = spark.read.csv("/opt/airflow/russian_houses.csv", header=False, inferSchema=True)
              ^^^^^^^^^^^^^^^^^^^^^^^^^^^^^^^^^^^^^^^^^^^^^^^^^^^^^^^^^^^^^^^^^^^^^^^^^^^^^^^^^
  File "/home/airflow/.local/lib/python3.12/site-packages/pyspark/sql/readwriter.py", line 727, in csv
    return self._df(self._jreader.csv(self._spark._sc._jvm.PythonUtils.toSeq(path)))
                    ^^^^^^^^^^^^^^^^^^^^^^^^^^^^^^^^^^^^^^^^^^^^^^^^^^^^^^^^^^^^^^^
  File "/opt/spark/spark-3.4.2-bin-hadoop3/python/lib/py4j-0.10.9.7-src.zip/py4j/java_gateway.py", line 1322, in __call__
    return_value = get_return_value(
                   ^^^^^^^^^^^^^^^^^
  File "/home/airflow/.local/lib/python3.12/site-packages/pyspark/errors/exceptions/captured.py", line 175, in deco
    raise converted from None
pyspark.errors.exceptions.captured.AnalysisException: [PATH_NOT_FOUND] Path does not exist: file:/opt/airflow/russian_houses.csv.

During handling of the above exception, another exception occurred:

Traceback (most recent call last):
  File "/home/airflow/.local/lib/python3.12/site-packages/airflow/models/taskinstance.py", line 465, in _execute_task
    result = _execute_callable(context=context, **execute_callable_kwargs)
             ^^^^^^^^^^^^^^^^^^^^^^^^^^^^^^^^^^^^^^^^^^^^^^^^^^^^^^^^^^^^^
  File "/home/airflow/.local/lib/python3.12/site-packages/airflow/models/taskinstance.py", line 432, in _execute_callable
    return execute_callable(context=context, **execute_callable_kwargs)
           ^^^^^^^^^^^^^^^^^^^^^^^^^^^^^^^^^^^^^^^^^^^^^^^^^^^^^^^^^^^^
  File "/home/airflow/.local/lib/python3.12/site-packages/airflow/models/baseoperator.py", line 401, in wrapper
    return func(self, *args, **kwargs)
           ^^^^^^^^^^^^^^^^^^^^^^^^^^^
  File "/home/airflow/.local/lib/python3.12/site-packages/airflow/operators/python.py", line 235, in execute
    return_value = self.execute_callable()
                   ^^^^^^^^^^^^^^^^^^^^^^^
  File "/home/airflow/.local/lib/python3.12/site-packages/airflow/operators/python.py", line 252, in execute_callable
    return self.python_callable(*self.op_args, **self.op_kwargs)
           ^^^^^^^^^^^^^^^^^^^^^^^^^^^^^^^^^^^^^^^^^^^^^^^^^^^^^
  File "/opt/airflow/dags/main.py", line 42, in DownloadCSV
    print(errno)
          ^^^^^
NameError: name 'errno' is not defined. Did you forget to import 'errno'
[2025-05-04T18:24:13.452+0000] {taskinstance.py:1206} INFO - Marking task as FAILED. dag_id=main, task_id=task_first, run_id=manual__2025-05-04T18:23:59.433782+00:00, execution_date=20250504T182359, start_date=20250504T182402, end_date=20250504T182413
[2025-05-04T18:24:13.482+0000] {standard_task_runner.py:110} ERROR - Failed to execute job 132 for task task_first (name 'errno' is not defined; 413)
[2025-05-04T18:24:13.506+0000] {local_task_job_runner.py:240} INFO - Task exited with return code 1
[2025-05-04T18:24:13.564+0000] {taskinstance.py:3503} INFO - 0 downstream tasks scheduled from follow-on schedule check
[2025-05-04T18:24:13.579+0000] {local_task_job_runner.py:222} INFO - ::endgroup::
